Workbook

Sheet Léeme
A1: Verificación de tiempos y precios — Cotizador Web (Alexander Woodcock)
A3: PROPÓSITO: verificar por tu cuenta que los tiempos y precios que muestra la web son correctos,
A4: y ajustar las horas según lo que realmente te demora. TODAS las cifras salen del mismo motor
A5: que usa la web (catalogCore.ts + rateCard.ts) — este Excel replica sus fórmulas.
A7: CÓMO USARLO:
A8: 1. Hoja CATÁLOGO: edita las HORAS (columnas min/max por nivel) de cualquier subtarea.
A9: Los precios COP de esa fila se recalculan solos (horas × tarifa por rol).
A10: 2. Hoja RESUMEN: totales por servicio y nivel (SUMIFS sobre Catálogo), con redondeo
A11: igual al de la web (mínimo hacia abajo, máximo hacia arriba, paso $1.000 COP).
A12: 3. Hoja TARIFAS: tarifa por rol COP/USD + benchmark Colombia/internacional.
A13: Si cambias una tarifa ahí, TODO el Excel y los precios se recalculan.
A14: 4. Hoja COTIZADOR WEB: qué decisión del wizard afecta qué tarea, con los umbrales
... A31: REGLA DE ENTREGA (días hábiles) usada por la web: ≈ horas_max ÷ 5,5 con colchón.

Sheet Tarifas
A1: Tarifa por rol — base de todos los cálculos
A3: Rol | B3: Clase | C3: COP min/h | D3: COP max/h | E3: USD min/h | F3: USD max/h
A4: Arte 3D / Render | B4: RC-ART | C4: 30000 | D4: 42000 | E4: 20 | F4: 28
A5: Asset Realtime | B5: RC-RTA | C5: 38000 | D5: 52000 | E5: 25 | F5: 35
A6: Dev Web 3D | B6: RC-WEB | C6: 40000 | D6: 57000 | E6: 27 | F6: 38
A7: IA aplicada | B7: RC-AI | C7: 42000 | D7: 60000 | E7: 28 | F7: 40
A8: Consultoría | B8: RC-CON | C8: 60000 | D8: 82000 | E8: 40 | F8: 55
A9: Proyecto mínimo (COP / USD) | C9: 400000 | E9: 100
A11: Benchmark de mercado (2025-2026) — referencia, no modifica fórmulas
A12: Perfil | B12: Colombia (COP/h) | C12: Internacional (USD/h) | D12: Fuente
A13: Dev frontend general — junior | B13: 60.000–100.000 | C13: $15–25/h | D13: omarhernandezrey.com
A14: Dev frontend general — mid/senior | B14: 100.000–240.000 | C14: $25–60/h | D14: omarhernandezrey.com
A15: Dev three.js/WebGL (LatAm, empleador) | B15: ≈ 80.000–85.000 | C15: ≈ $20/h | D15: hireinsouth.com
A16: Modelador 3D con experiencia | B16: 40.000–60.000 | C16: ≈ $10–15/h | D16: comunidad diseñadores industriales CO
A17: Diseño profesional (tarifario 2025) | B17: ≈ 90.000 | C17: — | D17: disenadorescolombianos.co
A18: 3D artistas internacionales | B18: ≈ 2,8M–4M /día | C18: $700–1.000/día | D18: benchmark global
A19: Chatbot IA conversacional (proyecto, CO) | B19: 6M–16M | C19: $1.500–4.000 | D19: consolidaciondigital.com
A20: Agente IA empresarial (proyecto) | B20: desde 4,9M | C20: $20.000–80.000 (techo intl.) | D20: mentoracolombia.com · kemenystudio.com
A22: Lectura: la tarifa RC-WEB actual (40–57 mil COP/h) está por debajo incluso del junior de mercado → margen de reventa sano para la agencia y margen de subida futuro. RC-ART (30–42 mil) está en línea con el modelador local experimentado.

Sheet Catálogo
A1: Servicio ID | B1: Servicio | C1: Familia | D1: Subtarea | E1: Clase | F1: XS min | G1: XS max | H1: S min | I1: S max | J1: M min | K1: M max | L1: L min | M1: L max | N1: XL min | O1: XL max | P1: XS COP min | Q1: XS COP max | R1: S COP min | S1: S COP max | T1: M COP min | U1: M COP max | V1: L COP min | W1: L COP max | X1: XL COP min | Y1: XL COP max | Z1: tarifa min | AA1: tarifa max
A2: RND-01 | B2: Render 3D estatico | C2: render | D2: Brief + moodboard | E2: RC-ART | F2: 0.5 | G2: 1 | H2: 0.5 | I2: 1 | J2: 1 | K2: 2 | L2: 1 | M2: 2 | N2: 2 | O2: 3 | R2: =F2*$AB2 | S2: =G2*$AC2 | T2: =H2*$AB2 | U2: =I2*$AC2 | V2: =J2*$AB2 | W2: =K2*$AC2 | X2: =L2*$AB2 | Y2: =M2*$AC2 | Z2: =N2*$AB2 | AA2: =O2*$AC2 | AB2: =VLOOKUP($E2,Tarifas!$B$4:$F$8,2,0) | AC2: =VLOOKUP($E2,Tarifas!$B$4:$F$8,3,0)
A3: RND-01 | B3: Render 3D estatico | C3: render | D3: Setup escena (camara, luz, HDRI) | E3: RC-ART | F3: 0.5 | G3: 1 | H3: 1 | I3: 2 | J3: 1.5 | K3: 3 | L3: 2 | M3: 5 | N3: 4 | O3: 8 | R3: =F3*$AB3 | S3: =G3*$AC3 | T3: =H3*$AB3 | U3: =I3*$AC3 | V3: =J3*$AB3 | W3: =K3*$AC3 | X3: =L3*$AB3 | Y3: =M3*$AC3 | Z3: =N3*$AB3 | AA3: =O3*$AC3 | AB3: =VLOOKUP($E3,Tarifas!$B$4:$F$8,2,0) | AC3: =VLOOKUP($E3,Tarifas!$B$4:$F$8,3,0)
A4: RND-01 | B4: Render 3D estatico | C4: render | D4: Materiales y texturizado | E4: RC-ART | F4: 0.5 | G4: 1.5 | H4: 1 | I4: 3 | J4: 2 | K4: 6 | L4: 4 | M4: 10 | N4: 8 | O4: 16 | R4: =F4*$AB4 | S4: =G4*$AC4 | T4: =H4*$AB4 | U4: =I4*$AC4 | V4: =J4*$AB4 | W4: =K4*$AC4 | X4: =L4*$AB4 | Y4: =M4*$AC4 | Z4: =N4*$AB4 | AA4: =O4*$AC4 | AB4: =VLOOKUP($E4,Tarifas!$B$4:$F$8,2,0) | AC4: =VLOOKUP($E4,Tarifas!$B$4:$F$8,3,0)
A5: RND-01 | B5: Render 3D estatico | C5: render | D5: Render + denoise | E5: RC-ART | F5: 0.5 | G5: 0.5 | H5: 0.5 | I5: 1 | J5: 1 | K5: 2 | L5: 1.5 | M5: 4 | N5: 3 | O5: 6 | R5: =F5*$AB5 | S5: =G5*$AC5 | T5: =H5*$AB5 | U5: =I5*$AC5 | V5: =J5*$AB5 | W5: =K5*$AC5 | X5: =L5*$AB5 | Y5: =M5*$AC5 | Z5: =N5*$AB5 | AA5: =O5*$AC5 | AB5: =VLOOKUP($E5,Tarifas!$B$4:$F$8,2,0) | AC5: =VLOOKUP($E5,Tarifas!$B$4:$F$8,3,0)
A6: RND-01 | B6: Render 3D estatico | C6: render | D6: Post-produccion | E6: RC-ART | F6: 0.25 | G6: 0.5 | H6: 0.5 | I6: 1 | J6: 1 | K6: 2 | L6: 2 | M6: 4 | N6: 4 | O6: 8 | R6: =F6*$AB6 | S6: =G6*$AC6 | T6: =H6*$AB6 | U6: =I6*$AC6 | V6: =J6*$AB6 | W6: =K6*$AC6 | X6: =L6*$AB6 | Y6: =M6*$AC6 | Z6: =N6*$AB6 | AA6: =O6*$AC6 | AB6: =VLOOKUP($E6,Tarifas!$B$4:$F$8,2,0) | AC6: =VLOOKUP($E6,Tarifas!$B$4:$F$8,3,0)
A7: RND-01 | B7: Render 3D estatico | C7: render | D7: QA + export | E7: RC-ART | F7: 0.25 | G7: 0.5 | H7: 0.5 | I7: 1 | J7: 0.5 | K7: 1 | L7: 0.5 | M7: 1 | N7: 1 | O7: 2 | R7: =F7*$AB7 | S7: =G7*$AC7 | T7: =H7*$AB7 | U7: =I7*$AC7 | V7: =J7*$AB7 | W7: =K7*$AC7 | X7: =L7*$AB7 | Y7: =M7*$AC7 | Z7: =N7*$AB7 | AA7: =O7*$AC7 | AB7: =VLOOKUP($E7,Tarifas!$B$4:$F$8,2,0) | AC7: =VLOOKUP($E7,Tarifas!$B$4:$F$8,3,0)
A8: RND-02 | B8: Animacion 3D (render offline) | C8: render | D8: Storyboard/previs | E8: RC-ART | F8: 0.5 | G8: 1 | H8: 2 | I8: 4 | J8: 3 | K8: 6 | L8: 4 | M8: 8 | N8: 6 | O8: 12 | R8: =F8*$AB8 | S8: =G8*$AC8 | T8: =H8*$AB8 | U8: =I8*$AC8 | V8: =J8*$AB8 | W8: =K8*$AC8 | X8: =L8*$AB8 | Y8: =M8*$AC8 | Z8: =N8*$AB8 | AA8: =O8*$AC8 | AB8: =VLOOKUP($E8,Tarifas!$B$4:$F$8,2,0) | AC8: =VLOOKUP($E8,Tarifas!$B$4:$F$8,3,0)
A9: RND-02 | B9: Animacion 3D (render offline) | C9: render | D9: Layout escena y camaras | E9: RC-ART | F9: 0.5 | G9: 1 | H9: 1 | I9: 2 | J9: 2 | K9: 4 | L9: 3 | M9: 6 | N9: 5 | O9: 8 | R9: =F9*$AB9 | S9: =G9*$AC9 | T9: =H9*$AB9 | U9: =I9*$AC9 | V9: =J9*$AB9 | W9: =K9*$AC9 | X9: =L9*$AB9 | Y9: =M9*$AC9 | Z9: =N9*$AB9 | AA9: =O9*$AC9 | AB9: =VLOOKUP($E9,Tarifas!$B$4:$F$8,2,0) | AC9: =VLOOKUP($E9,Tarifas!$B$4:$F$8,3,0)
A10: RND-02 | B10: Animacion 3D (render offline) | C10: render | D10: Animacion (camara/objetos) | E10: RC-ART | F10: 1 | G10: 2 | H10: 4 | I10: 8 | J10: 8 | K10: 16 | L10: 12 | M10: 24 | N10: 20 | O10: 40 | R10: =F10*$AB10 | S10: =G10*$AC10 | T10: =H10*$AB10 | U10: =I10*$AC10 | V10: =J10*$AB10 | W10: =K10*$AC10 | X10: =L10*$AB10 | Y10: =M10*$AC10 | Z10: =N10*$AB10 | AA10: =O10*$AC10 | AB10: =VLOOKUP($E10,Tarifas!$B$4:$F$8,2,0) | AC10: =VLOOKUP($E10,Tarifas!$B$4:$F$8,3,0)
A11: RND-02 | B11: Animacion 3D (render offline) | C11: render | D11: Iluminacion + lookdev | E11: RC-ART | F11: 1 | G11: 2 | H11: 2 | I11: 4 | J11: 4 | K11: 7 | L11: 5 | M11: 10 | N11: 8 | O11: 14 | R11: =F11*$AB11 | S11: =G11*$AC11 | T11: =H11*$AB11 | U11: =I11*$AC11 | V11: =J11*$AB11 | W11: =K11*$AC11 | X11: =L11*$AB11 | Y11: =M11*$AC11 | Z11: =N11*$AB11 | AA11: =O11*$AC11 | AB11: =VLOOKUP($E11,Tarifas!$B$4:$F$8,2,0) | AC11: =VLOOKUP($E11,Tarifas!$B$4:$F$8,3,0)
A12: RND-02 | B12: Animacion 3D (render offline) | C12: render | D12: Renders/passes | E12: RC-ART | F12: 1 | G12: 1.5 | H12: 2 | I12: 3 | J12: 3 | K12: 5 | L12: 4 | M12: 8 | N12: 6 | O12: 12 | R12: =F12*$AB12 | S12: =G12*$AC12 | T12: =H12*$AB12 | U12: =I12*$AC12 | V12: =J12*$AB12 | W12: =K12*$AC12 | X12: =L12*$AB12 | Y12: =M12*$AC12 | Z12: =N12*$AB12 | AA12: =O12*$AC12 | AB12: =VLOOKUP($E12,Tarifas!$B$4:$F$8,2,0) | AC12: =VLOOKUP($E12,Tarifas!$B$4:$F$8,3,0)
A13: RND-02 | B13: Animacion 3D (render offline) | C13: render | D13: Composicion, edit, grade | E13: RC-ART | F13: 1 | G13: 1.5 | H13: 2 | I13: 3 | J13: 3 | K13: 5 | L13: 4 | M13: 8 | N13: 6 | O13: 12 | R13: =F13*$AB13 | S13: =G13*$AC13 | T13: =H13*$AB13 | U13: =I13*$AC13 | V13: =J13*$AB13 | W13: =K13*$AC13 | X13: =L13*$AB13 | Y13: =M13*$AC13 | Z13: =N13*$AB13 | AA13: =O13*$AC13 | AB13: =VLOOKUP($E13,Tarifas!$B$4:$F$8,2,0) | AC13: =VLOOKUP($E13,Tarifas!$B$4:$F$8,3,0)
... A115: PIPE-01 | B115: Automatizacion de pipeline/scripts/tools | C115: pipeline | D115: Pipeline completo end-to-end documentado + QA auto | E115: RC-AI | F115: 0 | G115: 0 | H115: 0 | I115: 0 | J115: 0 | K115: 0 | L115: 30 | M115: 80 | N115: 36 | O115: 96 | R115: =F115*$AB115 | S115: =G115*$AC115 | T115: =H115*$AB115 | U115: =I115*$AC115 | V115: =J115*$AB115 | W115: =K115*$AC115 | X115: =L115*$AB115 | Y115: =M115*$AC115 | Z115: =N115*$AB115 | AA115: =O115*$AC115 | AB115: =VLOOKUP($E115,Tarifas!$B$4:$F$8,2,0) | AC115: =VLOOKUP($E115,Tarifas!$B$4:$F$8,3,0)

Sheet Resumen Servicios
A1: ID | B1: Servicio | C1: Familia | D1: Entrega (d) | E1: XS h min | F1: XS h max | G1: XS COP min | H1: XS COP max | I1: S h min | J1: S h max | K1: S COP min | L1: S COP max | M1: M h min | N1: M h max | O1: M COP min | P1: M COP max | Q1: L h min | R1: L h max | S1: L COP min | T1: L COP max | U1: XL h min | V1: XL h max | W1: XL COP min | X1: XL COP max | Y1: Desde (COP, S) | AA1: XS RAW min | AB1: XS RAW max | AC1: S RAW min | AD1: S RAW max | AE1: M RAW min | AF1: M RAW max | AG1: L RAW min | AH1: L RAW max | AI1: XL RAW min | AJ1: XL RAW max
A2: RND-01 | B2: Render 3D estatico | C2: render | D2: 1-14 | E2: =IF(SUMIFS(Catálogo!$F:$F,Catálogo!$A:$A,$A2)=0,SUMIFS(Catálogo!$H:$H,Catálogo!$A:$A,$A2),SUMIFS(Catálogo!$F:$F,Catálogo!$A:$A,$A2)) | F2: =IF(SUMIFS(Catálogo!$G:$G,Catálogo!$A:$A,$A2)=0,SUMIFS(Catálogo!$I:$I,Catálogo!$A:$A,$A2),SUMIFS(Catálogo!$G:$G,Catálogo!$A:$A,$A2)) | G2: =IF(SUMIFS(Catálogo!$F:$F,Catálogo!$A:$A,$A2)=0,MAX(FLOOR(SUMIFS(Catálogo!$T:$T,Catálogo!$A:$A,$A2),1000),400000),MAX(FLOOR(SUMIFS(Catálogo!$R:$R,Catálogo!$A:$A,$A2),1000),400000)) | H2: =IF(SUMIFS(Catálogo!$G:$G,Catálogo!$A:$A,$A2)=0,MAX(CEILING(SUMIFS(Catálogo!$U:$U,Catálogo!$A:$A,$A2),1000),400000),MAX(CEILING(SUMIFS(Catálogo!$S:$S,Catálogo!$A:$A,$A2),1000),400000)) | I2: =SUMIFS(Catálogo!$H:$H,Catálogo!$A:$A,$A2) | J2: =SUMIFS(Catálogo!$I:$I,Catálogo!$A:$A,$A2) | K2: =MAX(FLOOR(SUMIFS(Catálogo!$T:T,Catálogo!$A:$A,$A2),1000),400000) | L2: =MAX(CEILING(SUMIFS(Catálogo!$U:U,Catálogo!$A:$A,$A2),1000),400000) | M2: =SUMIFS(Catálogo!$J:$J,Catálogo!$A:$A,$A2) | N2: =SUMIFS(Catálogo!$K:$K,Catálogo!$A:$A,$A2) | O2: =MAX(FLOOR(SUMIFS(Catálogo!$V:V,Catálogo!$A:$A,$A2),1000),400000) | P2: =MAX(CEILING(SUMIFS(Catálogo!$W:W,Catálogo!$A:$A,$A2),1000),400000) | Q2: =SUMIFS(Catálogo!$L:$L,Catálogo!$A:$A,$A2) | R2: =SUMIFS(Catálogo!$M:$M,Catálogo!$A:$A,$A2) | S2: =MAX(FLOOR(SUMIFS(Catálogo!$X:X,Catálogo!$A:$A,$A2),1000),400000) | T2: =MAX(CEILING(SUMIFS(Catálogo!$Y:Y,Catálogo!$A:$A,$A2),1000),400000) | U2: =SUMIFS(Catálogo!$N:$N,Catálogo!$A:$A,$A2) | V2: =SUMIFS(Catálogo!$O:$O,Catálogo!$A:$A,$A2) | W2: =MAX(FLOOR(SUMIFS(Catálogo!$Z:Z,Catálogo!$A:$A,$A2),1000),400000) | X2: =MAX(CEILING(SUMIFS(Catálogo!$AA:AA,Catálogo!$A:$A,$A2),1000),400000) | Y2: =K2 | AA2: =SUMIFS(Catálogo!$F:$F,Catálogo!$A:$A,$A2) | AB2: =SUMIFS(Catálogo!$Z:Z,Catálogo!$A:$A,$A2) | AC2: =SUMIFS(Catálogo!$H:$H,Catálogo!$A:$A,$A2) | AD2: =SUMIFS(Catálogo!$Z:Z,Catálogo!$A:$A,$A2) | AE2: =SUMIFS(Catálogo!$J:$J,Catálogo!$A:$A,$A2) | AF2: =SUMIFS(Catálogo!$Z:Z,Catálogo!$A:$A,$A2) | AG2: =SUMIFS(Catálogo!$L:$L,Catálogo!$A:$A,$A2) | AH2: =SUMIFS(Catálogo!$Z:Z,Catálogo!$A:$A,$A2) | AI2: =SUMIFS(Catálogo!$N:$N,Catálogo!$A:$A,$A2) | AJ2: =SUMIFS(Catálogo!$Z:Z,Catálogo!$A:$A,$A2)
A3: RND-02 | B3: Animacion 3D (render offline) | C3: render | D3: 3-42 | E3: =IF(SUMIFS(Catálogo!$F:$F,Catálogo!$A:$A,$A3)=0,SUMIFS(Catálogo!$H:$H,Catálogo!$A:$A,$A3),SUMIFS(Catálogo!$F:$F,Catálogo!$A:$A,$A3)) | F3: =IF(SUMIFS(Catálogo!$G:$G,Catálogo!$A:$A,$A3)=0,SUMIFS(Catálogo!$I:$I,Catálogo!$A:$A,$A3),SUMIFS(Catálogo!$G:$G,Catálogo!$A:$A,$A3)) | G3: =IF(SUMIFS(Catálogo!$F:$F,Catálogo!$A:$A,$A3)=0,MAX(FLOOR(SUMIFS(Catálogo!$T:$T,Catálogo!$A:$A,$A3),1000),400000),MAX(FLOOR(SUMIFS(Catálogo!$R:$R,Catálogo!$A:$A,$A3),1000),400000)) | H3: =IF(SUMIFS(Catálogo!$G:$G,Catálogo!$A:$A,$A3)=0,MAX(CEILING(SUMIFS(Catálogo!$U:$U,Catálogo!$A:$A,$A3),1000),400000),MAX(CEILING(SUMIFS(Catálogo!$S:$S,Catálogo!$A:$A,$A3),1000),400000)) | I3: =SUMIFS(Catálogo!$H:$H,Catálogo!$A:$A,$A3) | J3: =SUMIFS(Catálogo!$I:$I,Catálogo!$A:$A,$A3) | K3: =MAX(FLOOR(SUMIFS(Catálogo!$T:T,Catálogo!$A:$A,$A3),1000),400000) | L3: =MAX(CEILING(SUMIFS(Catálogo!$U:U,Catálogo!$A:$A,$A3),1000),400000) | M3: =SUMIFS(Catálogo!$J:$J,Catálogo!$A:$A,$A3) | N3: =SUMIFS(Catálogo!$K:$K,Catálogo!$A:$A,$A3) | O3: =MAX(FLOOR(SUMIFS(Catálogo!$V:V,Catálogo!$A:$A,$A3),1000),400000) | P3: =MAX(CEILING(SUMIFS(Catálogo!$W:W,Catálogo!$A:$A,$A3),1000),400000) | Q3: =SUMIFS(Catálogo!$L:$L,Catálogo!$A:$A,$A3) | R3: =SUMIFS(Catálogo!$M:$M,Catálogo!$A:$A,$A3) | S3: =MAX(FLOOR(SUMIFS(Catálogo!$X:X,Catálogo!$A:$A,$A3),1000),400000) | T3: =MAX(CEILING(SUMIFS(Catálogo!$Y:Y,Catálogo!$A:$A,$A3),1000),400000) | U3: =SUMIFS(Catálogo!$N:$N,Catálogo!$A:$A,$A3) | V3: =SUMIFS(Catálogo!$O:$O,Catálogo!$A:$A,$A3) | W3: =MAX(FLOOR(SUMIFS(Catálogo!$Z:Z,Catálogo!$A:$A,$A3),1000),400000) | X3: =MAX(CEILING(SUMIFS(Catálogo!$AA:AA,Catálogo!$A:$A,$A3),1000),400000) | Y3: =K3 | AA3: =SUMIFS(Catálogo!$F:$F,Catálogo!$A:$A,$A3) | AB3: =SUMIFS(Catálogo!$Z:Z,Catálogo!$A:$A,$A3) | AC3: =SUMIFS(Catálogo!$H:$H,Catálogo!$A:$A,$A3) | AD3: =SUMIFS(Catálogo!$Z:Z,Catálogo!$A:$A,$A3) | AE3: =SUMIFS(Catálogo!$J:$J,Catálogo!$A:$A,$A3) | AF3: =SUMIFS(Catálogo!$Z:Z,Catálogo!$A:$A,$A3) | AG3: =SUMIFS(Catálogo!$L:$L,Catálogo!$A:$A,$A3) | AH3: =SUMIFS(Catálogo!$Z:Z,Catálogo!$A:$A,$A3) | AI3: =SUMIFS(Catálogo!$N:$N,Catálogo!$A:$A,$A3) | AJ3: =SUMIFS(Catálogo!$Z:Z,Catálogo!$A:$A,$A3)
A4: RTA-01 | B4: Asset 3D realtime estatico | C4: asset-rt | D4: 1-42 | E4: =IF(SUMIFS(Catálogo!$F:$F,Catálogo!$A:$A,$A4)=0,SUMIFS(Catálogo!$H:$H,Catálogo!$A:$A,$A4),SUMIFS(Catálogo!$F:$F,Catálogo!$A:$A,$A4)) | F4: =IF(SUMIFS(Catálogo!$G:$G,Catálogo!$A:$A,$A4)=0,SUMIFS(Catálogo!$I:$I,Catálogo!$A:$A,$A4),SUMIFS(Catálogo!$G:$G,Catálogo!$A:$A,$A4)) | G4: =IF(SUMIFS(Catálogo!$F:$F,Catálogo!$A:$A,$A4)=0,MAX(FLOOR(SUMIFS(Catálogo!$T:$T,Catálogo!$A:$A,$A4),1000),400000),MAX(FLOOR(SUMIFS(Catálogo!$R:$R,Catálogo!$A:$A,$A4),1000),400000)) | H4: =IF(SUMIFS(Catálogo!$G:$G,Catálogo!$A:$A,$A4)=0,MAX(CEILING(SUMIFS(Catálogo!$U:$U,Catálogo!$A:$A,$A4),1000),400000),MAX(CEILING(SUMIFS(Catálogo!$S:$S,Catálogo!$A:$A,$A4),1000),400000)) | I4: =SUMIFS(Catálogo!$H:$H,Catálogo!$A:$A,$A4) | J4: =SUMIFS(Catálogo!$I:$I,Catálogo!$A:$A,$A4) | K4: =MAX(FLOOR(SUMIFS(Catálogo!$T:T,Catálogo!$A:$A,$A4),1000),400000) | L4: =MAX(CEILING(SUMIFS(Catálogo!$U:U,Catálogo!$A:$A,$A4),1000),400000) | M4: =SUMIFS(Catálogo!$J:$J,Catálogo!$A:$A,$A4) | N4: =SUMIFS(Catálogo!$K:$K,Catálogo!$A:$A,$A4) | O4: =MAX(FLOOR(SUMIFS(Catálogo!$V:V,Catálogo!$A:$A,$A4),1000),400000) | P4: =MAX(CEILING(SUMIFS(Catálogo!$W:W,Catálogo!$A:$A,$A4),1000),400000) | Q4: =SUMIFS(Catálogo!$L:$L,Catálogo!$A:$A,$A4) | R4: =SUMIFS(Catálogo!$M:$M,Catálogo!$A:$A,$A4) | S4: =MAX(FLOOR(SUMIFS(Catálogo!$X:X,Catálogo!$A:$A,$A4),1000),400000) | T4: =MAX(CEILING(SUMIFS(Catálogo!$Y:Y,Catálogo!$A:$A,$A4),1000),400000) | U4: =SUMIFS(Catálogo!$N:$N,Catálogo!$A:$A,$A4) | V4: =SUMIFS(Catálogo!$O:$O,Catálogo!$A:$A,$A4) | W4: =MAX(FLOOR(SUMIFS(Catálogo!$Z:Z,Catálogo!$A:$A,$A4),1000),400000) | X4: =MAX(CEILING(SUMIFS(Catálogo!$AA:AA,Catálogo!$A:$A,$A4),1000),400000) | Y4: =K4 | AA4: =SUMIFS(Catálogo!$F:$F,Catálogo!$A:$A,$A4) | AB4: =SUMIFS(Catálogo!$Z:Z,Catálogo!$A:$A,$A4) | AC4: =SUMIFS(Catálogo!$H:$H,Catálogo!$A:$A,$A4) | AD4: =SUMIFS(Catálogo!$Z:Z,Catálogo!$A:$A,$A4) | AE4: =SUMIFS(Catálogo!$J:$J,Catálogo!$A:$A,$A4) | AF4: =SUMIFS(Catálogo!$Z:Z,Catálogo!$A:$A,$A4) | AG4: =SUMIFS(Catálogo!$L:$L,Catálogo!$A:$A,$A4) | AH4: =SUMIFS(Catálogo!$Z:Z,Catálogo!$A:$A,$A4) | AI4: =SUMIFS(Catálogo!$N:$N,Catálogo!$A:$A,$A4) | AJ4: =SUMIFS(Catálogo!$Z:Z,Catálogo!$A:$A,$A4)
A5: RTA-02 | B5: Asset RT interactuable (hotspots) | C5: asset-rt | D5: 2-49 | E5: =IF(SUMIFS(Catálogo!$F:$F,Catálogo!$A:$A,$A5)=0,SUMIFS(Catálogo!$H:$H,Catálogo!$A:$A,$A5),SUMIFS(Catálogo!$F:$F,Catálogo!$A:$A,$A5)) | F5: =IF(SUMIFS(Catálogo!$G:$G,Catálogo!$A:$A,$A5)=0,SUMIFS(Catálogo!$I:$I,Catálogo!$A:$A,$A5),SUMIFS(Catálogo!$G:$G,Catálogo!$A:$A,$A5)) | G5: =IF(SUMIFS(Catálogo!$F:$F,Catálogo!$A:$A,$A5)=0,MAX(FLOOR(SUMIFS(Catálogo!$T:$T,Catálogo!$A:$A,$A5),1000),400000),MAX(FLOOR(SUMIFS(Catálogo!$R:$R,Catálogo!$A:$A,$A5),1000),400000)) | H5: =IF(SUMIFS(Catálogo!$G:$G,Catálogo!$A:$A,$A5)=0,MAX(CEILING(SUMIFS(Catálogo!$U:$U,Catálogo!$A:$A,$A5),1000),400000),MAX(CEILING(SUMIFS(Catálogo!$S:$S,Catálogo!$A:$A,$A5),1000),400000)) | I5: =SUMIFS(Catálogo!$H:$H,Catálogo!$A:$A,$A5) | J5: =SUMIFS(Catálogo!$I:$I,Catálogo!$A:$A,$A5) | K5: =MAX(FLOOR(SUMIFS(Catálogo!$T:T,Catálogo!$A:$A,$A5),1000),400000) | L5: =MAX(CEILING(SUMIFS(Catálogo!$U:U,Catálogo!$A:$A,$A5),1000),400000) | M5: =SUMIFS(Catálogo!$J:$J,Catálogo!$A:$A,$A5) | N5: =SUMIFS(Catálogo!$K:$K,Catálogo!$A:$A,$A5) | O5: =MAX(FLOOR(SUMIFS(Catálogo!$V:V,Catálogo!$A:$A,$A5),1000),400000) | P5: =MAX(CEILING(SUMIFS(Catálogo!$W:W,Catálogo!$A:$A,$A5),1000),400000) | Q5: =SUMIFS(Catálogo!$L:$L,Catálogo!$A:$A,$A5) | R5: =SUMIFS(Catálogo!$M:$M,Catálogo!$A:$A,$A5) | S5: =MAX(FLOOR(SUMIFS(Catálogo!$X:X,Catálogo!$A:$A,$A5),1000),400000) | T5: =MAX(CEILING(SUMIFS(Catálogo!$Y:Y,Catálogo!$A:$A,$A5),1000),400000) | U5: =SUMIFS(Catálogo!$N:$N,Catálogo!$A:$A,$A5) | V5: =SUMIFS(Catálogo!$O:$O,Catálogo!$A:$A,$A5) | W5: =MAX(FLOOR(SUMIFS(Catálogo!$Z:Z,Catálogo!$A:$A,$A5),1000),400000) | X5: =MAX(CEILING(SUMIFS(Catálogo!$AA:AA,Catálogo!$A:$A,$A5),1000),400000) | Y5: =K5 | AA5: =SUMIFS(Catálogo!$F:$F,Catálogo!$A:$A,$A5) | AB5: =SUMIFS(Catálogo!$Z:Z,Catálogo!$A:$A,$A5) | AC5: =SUMIFS(Catálogo!$H:$H,Catálogo!$A:$A,$A5) | AD5: =SUMIFS(Catálogo!$Z:Z,Catálogo!$A:$A,$A5) | AE5: =SUMIFS(Catálogo!$J:$J,Catálogo!$A:$A,$A5) | AF5: =SUMIFS(Catálogo!$Z:Z,Catálogo!$A:$A,$A5) | AG5: =SUMIFS(Catálogo!$L:$L,Catálogo!$A:$A,$A5) | AH5: =SUMIFS(Catálogo!$Z:Z,Catálogo!$A:$A,$A5) | AI5: =SUMIFS(Catálogo!$N:$N,Catálogo!$A:$A,$A5) | AJ5: =SUMIFS(Catálogo!$Z:Z,Catálogo!$A:$A,$A5)
A6: CAD-01 | B6: CAD a WebGL ready (servicio insignia) | C6: datos | D6: 1-70 | E6: =IF(SUMIFS(Catálogo!$F:$F,Catálogo!$A:$A,$A6)=0,SUMIFS(Catálogo!$H:$H,Catálogo!$A:$A,$A6),SUMIFS(Catálogo!$F:$F,Catálogo!$A:$A,$A6)) | F6: =IF(SUMIFS(Catálogo!$G:$G,Catálogo!$A:$A,$A6)=0,SUMIFS(Catálogo!$I:$I,Catálogo!$A:$A,$A6),SUMIFS(Catálogo!$G:$G,Catálogo!$A:$A,$A6)) | G6: =IF(SUMIFS(Catálogo!$F:$F,Catálogo!$A:$A,$A6)=0,MAX(FLOOR(SUMIFS(Catálogo!$T:$T,Catálogo!$A:$A,$A6),1000),400000),MAX(FLOOR(SUMIFS(Catálogo!$R:$R,Catálogo!$A:$A,$A6),1000),400000)) | H6: =IF(SUMIFS(Catálogo!$G:$G,Catálogo!$A:$A,$A6)=0,MAX(CEILING(SUMIFS(Catálogo!$U:$U,Catálogo!$A:$A,$A6),1000),400000),MAX(CEILING(SUMIFS(Catálogo!$S:$S,Catálogo!$A:$A,$A6),1000),400000)) | I6: =SUMIFS(Catálogo!$H:$H,Catálogo!$A:$A,$A6) | J6: =SUMIFS(Catálogo!$I:$I,Catálogo!$A:$A,$A6) | K6: =MAX(FLOOR(SUMIFS(Catálogo!$T:T,Catálogo!$A:$A,$A6),1000),400000) | L6: =MAX(CEILING(SUMIFS(Catálogo!$U:U,Catálogo!$A:$A,$A6),1000),400000) | M6: =SUMIFS(Catálogo!$J:$J,Catálogo!$A:$A,$A6) | N6: =SUMIFS(Catálogo!$K:$K,Catálogo!$A:$A,$A6) | O6: =MAX(FLOOR(SUMIFS(Catálogo!$V:V,Catálogo!$A:$A,$A6),1000),400000) | P6: =MAX(CEILING(SUMIFS(Catálogo!$W:W,Catálogo!$A:$A,$A6),1000),400000) | Q6: =SUMIFS(Catálogo!$L:$L,Catálogo!$A:$A,$A6) | R6: =SUMIFS(Catálogo!$M:$M,Catálogo!$A:$A,$A6) | S6: =MAX(FLOOR(SUMIFS(Catálogo!$X:X,Catálogo!$A:$A,$A6),1000),400000) | T6: =MAX(CEILING(SUMIFS(Catálogo!$Y:Y,Catálogo!$A:$A,$A6),1000),400000) | U6: =SUMIFS(Catálogo!$N:$N,Catálogo!$A:$A,$A6) | V6: =SUMIFS(Catálogo!$O:$O,Catálogo!$A:$A,$A6) | W6: =MAX(FLOOR(SUMIFS(Catálogo!$Z:Z,Catálogo!$A:$A,$A6),1000),400000) | X6: =MAX(CEILING(SUMIFS(Catálogo!$AA:AA,Catálogo!$A:$A,$A6),1000),400000) | Y6: =K6 | AA6: =SUMIFS(Catálogo!$F:$F,Catálogo!$A:$A,$A6) | AB6: =SUMIFS(Catálogo!$Z:Z,Catálogo!$A:$A,$A6) | AC6: =SUMIFS(Catálogo!$H:$H,Catálogo!$A:$A,$A6) | AD6: =SUMIFS(Catálogo!$Z:Z,Catálogo!$A:$A,$A6) | AE6: =SUMIFS(Catálogo!$J:$J,Catálogo!$A:$A,$A6) | AF6: =SUMIFS(Catálogo!$Z:Z,Catálogo!$A:$A,$A6) | AG6: =SUMIFS(Catálogo!$L:$L,Catálogo!$A:$A,$A6) | AH6: =SUMIFS(Catálogo!$Z:Z,Catálogo!$A:$A,$A6) | AI6: =SUMIFS(Catálogo!$N:$N,Catálogo!$A:$A,$A6) | AJ6: =SUMIFS(Catálogo!$Z:Z,Catálogo!$A:$A,$A6)
A7: WEB-01 | B7: Visor custom three.js / Babylon.js | C7: web-3d | D7: 2-21 | E7: =IF(SUMIFS(Catálogo!$F:$F,Catálogo!$A:$A,$A7)=0,SUMIFS(Catálogo!$H:$H,Catálogo!$A:$A,$A7),SUMIFS(Catálogo!$F:$F,Catálogo!$A:$A,$A7)) | F7: =IF(SUMIFS(Catálogo!$G:$G,Catálogo!$A:$A,$A7)=0,SUMIFS(Catálogo!$I:$I,Catálogo!$A:$A,$A7),SUMIFS(Catálogo!$G:$G,Catálogo!$A:$A,$A7)) | G7: =IF(SUMIFS(Catálogo!$F:$F,Catálogo!$A:$A,$A7)=0,MAX(FLOOR(SUMIFS(Catálogo!$T:$T,Catálogo!$A:$A,$A7),1000),400000),MAX(FLOOR(SUMIFS(Catálogo!$R:$R,Catálogo!$A:$A,$A7),1000),400000)) | H7: =IF(SUMIFS(Catálogo!$G:$G,Catálogo!$A:$A,$A7)=0,MAX(CEILING(SUMIFS(Catálogo!$U:$U,Catálogo!$A:$A,$A7),1000),400000),MAX(CEILING(SUMIFS(Catálogo!$S:$S,Catálogo!$A:$A,$A7),1000),400000)) | I7: =SUMIFS(Catálogo!$H:$H,Catálogo!$A:$A,$A7) | J7: =SUMIFS(Catálogo!$I:$I,Catálogo!$A:$A,$A7) | K7: =MAX(FLOOR(SUMIFS(Catálogo!$T:T,Catálogo!$A:$A,$A7),1000),400000) | L7: =MAX(CEILING(SUMIFS(Catálogo!$U:U,Catálogo!$A:$A,$A7),1000),400000) | M7: =SUMIFS(Catálogo!$J:$J,Catálogo!$A:$A,$A7) | N7: =SUMIFS(Catálogo!$K:$K,Catálogo!$A:$A,$A7) | O7: =MAX(FLOOR(SUMIFS(Catálogo!$V:V,Catálogo!$A:$A,$A7),1000),400000) | P7: =MAX(CEILING(SUMIFS(Catálogo!$W:W,Catálogo!$A:$A,$A7),1000),400000) | Q7: =SUMIFS(Catálogo!$L:$L,Catálogo!$A:$A,$A7) | R7: =SUMIFS(Catálogo!$M:$M,Catálogo!$A:$A,$A7) | S7: =MAX(FLOOR(SUMIFS(Catálogo!$X:X,Catálogo!$A:$A,$A7),1000),400000) | T7: =MAX(CEILING(SUMIFS(Catálogo!$Y:Y,Catálogo!$A:$A,$A7),1000),400000) | U7: =SUMIFS(Catálogo!$N:$N,Catálogo!$A:$A,$A7) | V7: =SUMIFS(Catálogo!$O:$O,Catálogo!$A:$A,$A7) | W7: =MAX(FLOOR(SUMIFS(Catálogo!$Z:Z,Catálogo!$A:$A,$A7),1000),400000) | X7: =MAX(CEILING(SUMIFS(Catálogo!$AA:AA,Catálogo!$A:$A,$A7),1000),400000) | Y7: =K7 | AA7: =SUMIFS(Catálogo!$F:$F,Catálogo!$A:$A,$A7) | AB7: =SUMIFS(Catálogo!$Z:Z,Catálogo!$A:$A,$A7) | AC7: =SUMIFS(Catálogo!$H:$H,Catálogo!$A:$A,$A7) | AD7: =SUMIFS(Catálogo!$Z:Z,Catálogo!$A:$A,$A7) | AE7: =SUMIFS(Catálogo!$J:$J,Catálogo!$A:$A,$A7) | AF7: =SUMIFS(Catálogo!$Z:Z,Catálogo!$A:$A,$A7) | AG7: =SUMIFS(Catálogo!$L:$L,Catálogo!$A:$A,$A7) | AH7: =SUMIFS(Catálogo!$Z:Z,Catálogo!$A:$A,$A7) | AI7: =SUMIFS(Catálogo!$N:$N,Catálogo!$A:$A,$A7) | AJ7: =SUMIFS(Catálogo!$Z:Z,Catálogo!$A:$A,$A7)
A8: WEB-04 | B8: Web App 3D (configurador/herramienta) | C8: web-3d | D8: 7-112 | E8: =IF(SUMIFS(Catálogo!$F:$F,Catálogo!$A:$A,$A8)=0,SUMIFS(Catálogo!$H:$H,Catálogo!$A:$A,$A8),SUMIFS(Catálogo!$F:$F,Catálogo!$A:$A,$A8)) | F8: =IF(SUMIFS(Catálogo!$G:$G,Catálogo!$A:$A,$A8)=0,SUMIFS(Catálogo!$I:$I,Catálogo!$A:$A,$A8),SUMIFS(Catálogo!$G:$G,Catálogo!$A:$A,$A8)) | G8: =IF(SUMIFS(Catálogo!$F:$F,Catálogo!$A:$A,$A8)=0,MAX(FLOOR(SUMIFS(Catálogo!$T:$T,Catálogo!$A:$A,$A8),1000),400000),MAX(FLOOR(SUMIFS(Catálogo!$R:$R,Catálogo!$A:$A,$A8),1000),400000)) | H8: =IF(SUMIFS(Catálogo!$G:$G,Catálogo!$A:$A,$A8)=0,MAX(CEILING(SUMIFS(Catálogo!$U:$U,Catálogo!$A:$A,$A8),1000),400000),MAX(CEILING(SUMIFS(Catálogo!$S:$S,Catálogo!$A:$A,$A8),1000),400000)) | I8: =SUMIFS(Catálogo!$H:$H,Catálogo!$A:$A,$A8) | J8: =SUMIFS(Catálogo!$I:$I,Catálogo!$A:$A,$A8) | K8: =MAX(FLOOR(SUMIFS(Catálogo!$T:T,Catálogo!$A:$A,$A8),1000),400000) | L8: =MAX(CEILING(SUMIFS(Catálogo!$U:U,Catálogo!$A:$A,$A8),1000),400000) | M8: =SUMIFS(Catálogo!$J:$J,Catálogo!$A:$A,$A8) | N8: =SUMIFS(Catálogo!$K:$K,Catálogo!$A:$A,$A8) | O8: =MAX(FLOOR(SUMIFS(Catálogo!$V:V,Catálogo!$A:$A,$A8),1000),400000) | P8: =MAX(CEILING(SUMIFS(Catálogo!$W:W,Catálogo!$A:$A,$A8),1000),400000) | Q8: =SUMIFS(Catálogo!$L:$L,Catálogo!$A:$A,$A8) | R8: =SUMIFS(Catálogo!$M:$M,Catálogo!$A:$A,$A8) | S8: =MAX(FLOOR(SUMIFS(Catálogo!$X:X,Catálogo!$A:$A,$A8),1000),400000) | T8: =MAX(CEILING(SUMIFS(Catálogo!$Y:Y,Catálogo!$A:$A,$A8),1000),400000) | U8: =SUMIFS(Catálogo!$N:$N,Catálogo!$A:$A,$A8) | V8: =SUMIFS(Catálogo!$O:$O,Catálogo!$A:$A,$A8) | W8: =MAX(FLOOR(SUMIFS(Catálogo!$Z:Z,Catálogo!$A:$A,$A8),1000),400000) | X8: =MAX(CEILING(SUMIFS(Catálogo!$AA:AA,Catálogo!$A:$A,$A8),1000),400000) | Y8: =K8 | AA8: =SUMIFS(Catálogo!$F:$F,Catálogo!$A:$A,$A8) | AB8: =SUMIFS(Catálogo!$Z:Z,Catálogo!$A:$A,$A8) | AC8: =SUMIFS(Catálogo!$H:$H,Catálogo!$A:$A,$A8) | AD8: =SUMIFS(Catálogo!$Z:Z,Catálogo!$A:$A,$A8) | AE8: =SUMIFS(Catálogo!$J:$J,Catálogo!$A:$A,$A8) | AF8: =SUMIFS(Catálogo!$Z:Z,Catálogo!$A:$A,$A8) | AG8: =SUMIFS(Catálogo!$L:$L,Catálogo!$A:$A,$A8) | AH8: =SUMIFS(Catálogo!$Z:Z,Catálogo!$A:$A,$A8) | AI8: =SUMIFS(Catálogo!$N:$N,Catálogo!$A:$A,$A8) | AJ8: =SUMIFS(Catálogo!$Z:Z,Catálogo!$A:$A,$A8)
A9: AI-01 | B9: Asistente IA en sitio web (chat RAG) | C9: ia | D9: 3-70 | E9: =IF(SUMIFS(Catálogo!$F:$F,Catálogo!$A:$A,$A9)=0,SUMIFS(Catálogo!$H:$H,Catálogo!$A:$A,$A9),SUMIFS(Catálogo!$F:$F,Catálogo!$A:$A,$A9)) | F9: =IF(SUMIFS(Catálogo!$G:$G,Catálogo!$A:$A,$A9)=0,SUMIFS(Catálogo!$I:$I,Catálogo!$A:$A,$A9),SUMIFS(Catálogo!$G:$G,Catálogo!$A:$A,$A9)) | G9: =IF(SUMIFS(Catálogo!$F:$F,Catálogo!$A:$A,$A9)=0,MAX(FLOOR(SUMIFS(Catálogo!$T:$T,Catálogo!$A:$A,$A9),1000),400000),MAX(FLOOR(SUMIFS(Catálogo!$R:$R,Catálogo!$A:$A,$A9),1000),400000)) | H9: =IF(SUMIFS(Catálogo!$G:$G,Catálogo!$A:$A,$A9)=0,MAX(CEILING(SUMIFS(Catálogo!$U:$U,Catálogo!$A:$A,$A9),1000),400000),MAX(CEILING(SUMIFS(Catálogo!$S:$S,Catálogo!$A:$A,$A9),1000),400000)) | I9: =SUMIFS(Catálogo!$H:$H,Catálogo!$A:$A,$A9) | J9: =SUMIFS(Catálogo!$I:$I,Catálogo!$A:$A,$A9) | K9: =MAX(FLOOR(SUMIFS(Catálogo!$T:T,Catálogo!$A:$A,$A9),1000),400000) | L9: =MAX(CEILING(SUMIFS(Catálogo!$U:U,Catálogo!$A:$A,$A9),1000),400000) | M9: =SUMIFS(Catálogo!$J:$J,Catálogo!$A:$A,$A9) | N9: =SUMIFS(Catálogo!$K:$K,Catálogo!$A:$A,$A9) | O9: =MAX(FLOOR(SUMIFS(Catálogo!$V:V,Catálogo!$A:$A,$A9),1000),400000) | P9: =MAX(CEILING(SUMIFS(Catálogo!$W:W,Catálogo!$A:$A,$A9),1000),400000) | Q9: =SUMIFS(Catálogo!$L:$L,Catálogo!$A:$A,$A9) | R9: =SUMIFS(Catálogo!$M:$M,Catálogo!$A:$A,$A9) | S9: =MAX(FLOOR(SUMIFS(Catálogo!$X:X,Catálogo!$A:$A,$A9),1000),400000) | T9: =MAX(CEILING(SUMIFS(Catálogo!$Y:Y,Catálogo!$A:$A,$A9),1000),400000) | U9: =SUMIFS(Catálogo!$N:$N,Catálogo!$A:$A,$A9) | V9: =SUMIFS(Catálogo!$O:$O,Catálogo!$A:$A,$A9) | W9: =MAX(FLOOR(SUMIFS(Catálogo!$Z:Z,Catálogo!$A:$A,$A9),1000),400000) | X9: =MAX(CEILING(SUMIFS(Catálogo!$AA:AA,Catálogo!$A:$A,$A9),1000),400000) | Y9: =K9 | AA9: =SUMIFS(Catálogo!$F:$F,Catálogo!$A:$A,$A9) | AB9: =SUMIFS(Catálogo!$Z:Z,Catálogo!$A:$A,$A9) | AC9: =SUMIFS(Catálogo!$H:$H,Catálogo!$A:$A,$A9) | AD9: =SUMIFS(Catálogo!$Z:Z,Catálogo!$A:$A,$A9) | AE9: =SUMIFS(Catálogo!$J:$J,Catálogo!$A:$A,$A9) | AF9: =SUMIFS(Catálogo!$Z:Z,Catálogo!$A:$A,$A9) | AG9: =SUMIFS(Catálogo!$L:$L,Catálogo!$A:$A,$A9) | AH9: =SUMIFS(Catálogo!$Z:Z,Catálogo!$A:$A,$A9) | AI9: =SUMIFS(Catálogo!$N:$N,Catálogo!$A:$A,$A9) | AJ9: =SUMIFS(Catálogo!$Z:Z,Catálogo!$A:$A,$A9)
A10: CON-01 | B10: Consultoria tecnica 3D / web | C10: soporte | D10: 2-10 | E10: =IF(SUMIFS(Catálogo!$F:$F,Catálogo!$A:$A,$A10)=0,SUMIFS(Catálogo!$H:$H,Catálogo!$A:$A,$A10),SUMIFS(Catálogo!$F:$F,Catálogo!$A:$A,$A10)) | F10: =IF(SUMIFS(Catálogo!$G:$G,Catálogo!$A:$A,$A10)=0,SUMIFS(Catálogo!$I:$I,Catálogo!$A:$A,$A10),SUMIFS(Catálogo!$G:$G,Catálogo!$A:$A,$A10)) | G10: =IF(SUMIFS(Catálogo!$F:$F,Catálogo!$A:$A,$A10)=0,MAX(FLOOR(SUMIFS(Catálogo!$T:$T,Catálogo!$A:$A,$A10),1000),400000),MAX(FLOOR(SUMIFS(Catálogo!$R:$R,Catálogo!$A:$A,$A10),1000),400000)) | H10: =IF(SUMIFS(Catálogo!$G:$G,Catálogo!$A:$A,$A10)=0,MAX(CEILING(SUMIFS(Catálogo!$U:$U,Catálogo!$A:$A,$A10),1000),400000),MAX(CEILING(SUMIFS(Catálogo!$S:$S,Catálogo!$A:$A,$A10),1000),400000)) | I10: =SUMIFS(Catálogo!$H:$H,Catálogo!$A:$A,$A10) | J10: =SUMIFS(Catálogo!$I:$I,Catálogo!$A:$A,$A10) | K10: =MAX(FLOOR(SUMIFS(Catálogo!$T:T,Catálogo!$A:$A,$A10),1000),400000) | L10: =MAX(CEILING(SUMIFS(Catálogo!$U:U,Catálogo!$A:$A,$A10),1000),400000) | M10: =SUMIFS(Catálogo!$J:$J,Catálogo!$A:$A,$A10) | N10: =SUMIFS(Catálogo!$K:$K,Catálogo!$A:$A,$A10) | O10: =MAX(FLOOR(SUMIFS(Catálogo!$V:V,Catálogo!$A:$A,$A10),1000),400000) | P10: =MAX(CEILING(SUMIFS(Catálogo!$W:W,Catálogo!$A:$A,$A10),1000),400000) | Q10: =SUMIFS(Catálogo!$L:$L,Catálogo!$A:$A,$A10) | R10: =SUMIFS(Catálogo!$M:$M,Catálogo!$A:$A,$A10) | S10: =MAX(FLOOR(SUMIFS(Catálogo!$X:X,Catálogo!$A:$A,$A10),1000),400000) | T10: =MAX(CEILING(SUMIFS(Catálogo!$Y:Y,Catálogo!$A:$A,$A10),1000),400000) | U10: =SUMIFS(Catálogo!$N:$N,Catálogo!$A:$A,$A10) | V10: =SUMIFS(Catálogo!$O:$O,Catálogo!$A:$A,$A10) | W10: =MAX(FLOOR(SUMIFS(Catálogo!$Z:Z,Catálogo!$A:$A,$A10),1000),400000) | X10: =MAX(CEILING(SUMIFS(Catálogo!$AA:AA,Catálogo!$A:$A,$A10),1000),400000) | Y10: =K10 | AA10: =SUMIFS(Catálogo!$F:$F,Catálogo!$A:$A,$A10) | AB10: =SUMIFS(Catálogo!$Z:Z,Catálogo!$A:$A,$A10) | AC10: =SUMIFS(Catálogo!$H:$H,Catálogo!$A:$A,$A10) | AD10: =SUMIFS(Catálogo!$Z:Z,Catálogo!$A:$A,$A10) | AE10: =SUMIFS(Catálogo!$J:$J,Catálogo!$A:$A,$A10) | AF10: =SUMIFS(Catálogo!$Z:Z,Catálogo!$A:$A,$A10) | AG10: =SUMIFS(Catálogo!$L:$L,Catálogo!$A:$A,$A10) | AH10: =SUMIFS(Catálogo!$Z:Z,Catálogo!$A:$A,$A10) | AI10: =SUMIFS(Catálogo!$N:$N,Catálogo!$A:$A,$A10) | AJ10: =SUMIFS(Catálogo!$Z:Z,Catálogo!$A:$A,$A10)
A11: RET-01 | B11: Retainer mensual | C11: soporte | D11: 0-0 | E11: =IF(SUMIFS(Catálogo!$F:$F,Catálogo!$A:$A,$A11)=0,SUMIFS(Catálogo!$H:$H,Catálogo!$A:$A,$A11),SUMIFS(Catálogo!$F:$F,Catálogo!$A:$A,$A11)) | F11: =IF(SUMIFS(Catálogo!$G:$G,Catálogo!$A:$A,$A11)=0,SUMIFS(Catálogo!$I:$I,Catálogo!$A:$A,$A11),SUMIFS(Catálogo!$G:$G,Catálogo!$A:$A,$A11)) | G11: =IF(SUMIFS(Catálogo!$F:$F,Catálogo!$A:$A,$A11)=0,MAX(FLOOR(SUMIFS(Catálogo!$T:$T,Catálogo!$A:$A,$A11),1000),400000),MAX(FLOOR(SUMIFS(Catálogo!$R:$R,Catálogo!$A:$A,$A11),1000),400000)) | H11: =IF(SUMIFS(Catálogo!$G:$G,Catálogo!$A:$A,$A11)=0,MAX(CEILING(SUMIFS(Catálogo!$U:$U,Catálogo!$A:$A,$A11),1000),400000),MAX(CEILING(SUMIFS(Catálogo!$S:$S,Catálogo!$A:$A,$A11),1000),400000)) | I11: =SUMIFS(Catálogo!$H:$H,Catálogo!$A:$A,$A11) | J11: =SUMIFS(Catálogo!$I:$I,Catálogo!$A:$A,$A11) | K11: =MAX(FLOOR(SUMIFS(Catálogo!$T:T,Catálogo!$A:$A,$A11),1000),400000) | L11: =MAX(CEILING(SUMIFS(Catálogo!$U:U,Catálogo!$A:$A,$A11),1000),400000) | M11: =SUMIFS(Catálogo!$J:$J,Catálogo!$A:$A,$A11) | N11: =SUMIFS(Catálogo!$K:$K,Catálogo!$A:$A,$A11) | O11: =MAX(FLOOR(SUMIFS(Catálogo!$V:V,Catálogo!$A:$A,$A11),1000),400000) | P11: =MAX(CEILING(SUMIFS(Catálogo!$W:W,Catálogo!$A:$A,$A11),1000),400000) | Q11: =SUMIFS(Catálogo!$L:$L,Catálogo!$A:$A,$A11) | R11: =SUMIFS(Catálogo!$M:$M,Catálogo!$A:$A,$A11) | S11: =MAX(FLOOR(SUMIFS(Catálogo!$X:X,Catálogo!$A:$A,$A11),1000),400000) | T11: =MAX(CEILING(SUMIFS(Catálogo!$Y:Y,Catálogo!$A:$A,$A11),1000),400000) | U11: =SUMIFS(Catálogo!$N:$N,Catálogo!$A:$A,$A11) | V11: =SUMIFS(Catálogo!$O:$O,Catálogo!$A:$A,$A11) | W11: =MAX(FLOOR(SUMIFS(Catálogo!$Z:Z,Catálogo!$A:$A,$A11),1000),400000) | X11: =MAX(CEILING(SUMIFS(Catálogo!$AA:AA,Catálogo!$A:$A,$A11),1000),400000) | Y11: =K11 | AA11: =SUMIFS(Catálogo!$F:$F,Catálogo!$A:$A,$A11) | AB11: =SUMIFS(Catálogo!$Z:Z,Catálogo!$A:$A,$A11) | AC11: =SUMIFS(Catálogo!$H:$H,Catálogo!$A:$A,$A11) | AD11: =SUMIFS(Catálogo!$Z:Z,Catálogo!$A:$A,$A11) | AE11: =SUMIFS(Catálogo!$J:$J,Catálogo!$A:$A,$A11) | AF11: =SUMIFS(Catálogo!$Z:Z,Catálogo!$A:$A,$A11) | AG11: =SUMIFS(Catálogo!$L:$L,Catálogo!$A:$A,$A11) | AH11: =SUMIFS(Catálogo!$Z:Z,Catálogo!$A:$A,$A11) | AI11: =SUMIFS(Catálogo!$N:$N,Catálogo!$A:$A,$A11) | AJ11: =SUMIFS(Catálogo!$Z:Z,Catálogo!$A:$A,$A11)
A12: RTA-03 | B12: Modelo animado no interactuable | C12: asset-rt | D12: 3-60 | E12: =IF(SUMIFS(Catálogo!$F:$F,Catálogo!$A:$A,$A12)=0,SUMIFS(Catálogo!$H:$H,Catálogo!$A:$A,$A12),SUMIFS(Catálogo!$F:$F,Catálogo!$A:$A,$A12)) | F12: =IF(SUMIFS(Catálogo!$G:$G,Catálogo!$A:$A,$A12)=0,SUMIFS(Catálogo!$I:$I,Catálogo!$A:$A,$A12),SUMIFS(Catálogo!$G:$G,Catálogo!$A:$A,$A12)) | G12: =IF(SUMIFS(Catálogo!$F:$F,Catálogo!$A:$A,$A12)=0,MAX(FLOOR(SUMIFS(Catálogo!$T:$T,Catálogo!$A:$A,$A12),1000),400000),MAX(FLOOR(SUMIFS(Catálogo!$R:$R,Catálogo!$A:$A,$A12),1000),400000)) | H12: =IF(SUMIFS(Catálogo!$G:$G,Catálogo!$A:$A,$A12)=0,MAX(CEILING(SUMIFS(Catálogo!$U:$U,Catálogo!$A:$A,$A12),1000),400000),MAX(CEILING(SUMIFS(Catálogo!$S:$S,Catálogo!$A:$A,$A12),1000),400000)) | I12: =SUMIFS(Catálogo!$H:$H,Catálogo!$A:$A,$A12) | J12: =SUMIFS(Catálogo!$I:$I,Catálogo!$A:$A,$A12) | K12: =MAX(FLOOR(SUMIFS(Catálogo!$T:T,Catálogo!$A:$A,$A12),1000),400000) | L12: =MAX(CEILING(SUMIFS(Catálogo!$U:U,Catálogo!$A:$A,$A12),1000),400000) | M12: =SUMIFS(Catálogo!$J:$J,Catálogo!$A:$A,$A12) | N12: =SUMIFS(Catálogo!$K:$K,Catálogo!$A:$A,$A12) | O12: =MAX(FLOOR(SUMIFS(Catálogo!$V:V,Catálogo!$A:$A,$A12),1000),400000) | P12: =MAX(CEILING(SUMIFS(Catálogo!$W:W,Catálogo!$A:$A,$A12),1000),400000) | Q12: =SUMIFS(Catálogo!$L:$L,Catálogo!$A:$A,$A12) | R12: =SUMIFS(Catálogo!$M:$M,Catálogo!$A:$A,$A12) | S12: =MAX(FLOOR(SUMIFS(Catálogo!$X:X,Catálogo!$A:$A,$A12),1000),400000) | T12: =MAX(CEILING(SUMIFS(Catálogo!$Y:Y,Catálogo!$A:$A,$A12),1000),400000) | U12: =SUMIFS(Catálogo!$N:$N,Catálogo!$A:$A,$A12) | V12: =SUMIFS(Catálogo!$O:$O,Catálogo!$A:$A,$A12) | W12: =MAX(FLOOR(SUMIFS(Catálogo!$Z:Z,Catálogo!$A:$A,$A12),1000),400000) | X12: =MAX(CEILING(SUMIFS(Catálogo!$AA:AA,Catálogo!$A:$A,$A12),1000),400000) | Y12: =K12 | AA12: =SUMIFS(Catálogo!$F:$F,Catálogo!$A:$A,$A12) | AB12: =SUMIFS(Catálogo!$Z:Z,Catálogo!$A:$A,$A12) | AC12: =SUMIFS(Catálogo!$H:$H,Catálogo!$A:$A,$A12) | AD12: =SUMIFS(Catálogo!$Z:Z,Catálogo!$A:$A,$A12) | AE12: =SUMIFS(Catálogo!$J:$J,Catálogo!$A:$A,$A12) | AF12: =SUMIFS(Catálogo!$Z:Z,Catálogo!$A:$A,$A12) | AG12: =SUMIFS(Catálogo!$L:$L,Catálogo!$A:$A,$A12) | AH12: =SUMIFS(Catálogo!$Z:Z,Catálogo!$A:$A,$A12) | AI12: =SUMIFS(Catálogo!$N:$N,Catálogo!$A:$A,$A12) | AJ12: =SUMIFS(Catálogo!$Z:Z,Catálogo!$A:$A,$A12)
A13: RTA-04 | B13: Modelo animado interactuable | C13: asset-rt | D13: 5-80 | E13: =IF(SUMIFS(Catálogo!$F:$F,Catálogo!$A:$A,$A13)=0,SUMIFS(Catálogo!$H:$H,Catálogo!$A:$A,$A13),SUMIFS(Catálogo!$F:$F,Catálogo!$A:$A,$A13)) | F13: =IF(SUMIFS(Catálogo!$G:$G,Catálogo!$A:$A,$A13)=0,SUMIFS(Catálogo!$I:$I,Catálogo!$A:$A,$A13),SUMIFS(Catálogo!$G:$G,Catálogo!$A:$A,$A13)) | G13: =IF(SUMIFS(Catálogo!$F:$F,Catálogo!$A:$A,$A13)=0,MAX(FLOOR(SUMIFS(Catálogo!$T:$T,Catálogo!$A:$A,$A13),1000),400000),MAX(FLOOR(SUMIFS(Catálogo!$R:$R,Catálogo!$A:$A,$A13),1000),400000)) | H13: =IF(SUMIFS(Catálogo!$G:$G,Catálogo!$A:$A,$A13)=0,MAX(CEILING(SUMIFS(Catálogo!$U:$U,Catálogo!$A:$A,$A13),1000),400000),MAX(CEILING(SUMIFS(Catálogo!$S:$S,Catálogo!$A:$A,$A13),1000),400000)) | I13: =SUMIFS(Catálogo!$H:$H,Catálogo!$A:$A,$A13) | J13: =SUMIFS(Catálogo!$I:$I,Catálogo!$A:$A,$A13) | K13: =MAX(FLOOR(SUMIFS(Catálogo!$T:T,Catálogo!$A:$A,$A13),1000),400000) | L13: =MAX(CEILING(SUMIFS(Catálogo!$U:U,Catálogo!$A:$A,$A13),1000),400000) | M13: =SUMIFS(Catálogo!$J:$J,Catálogo!$A:$A,$A13) | N13: =SUMIFS(Catálogo!$K:$K,Catálogo!$A:$A,$A13) | O13: =MAX(FLOOR(SUMIFS(Catálogo!$V:V,Catálogo!$A:$A,$A13),1000),400000) | P13: =MAX(CEILING(SUMIFS(Catálogo!$W:W,Catálogo!$A:$A,$A13),1000),400000) | Q13: =SUMIFS(Catálogo!$L:$L,Catálogo!$A:$A,$A13) | R13: =SUMIFS(Catálogo!$M:$M,Catálogo!$A:$A,$A13) | S13: =MAX(FLOOR(SUMIFS(Catálogo!$X:X,Catálogo!$A:$A,$A13),1000),400000) | T13: =MAX(CEILING(SUMIFS(Catálogo!$Y:Y,Catálogo!$A:$A,$A13),1000),400000) | U13: =SUMIFS(Catálogo!$N:$N,Catálogo!$A:$A,$A13) | V13: =SUMIFS(Catálogo!$O:$O,Catálogo!$A:$A,$A13) | W13: =MAX(FLOOR(SUMIFS(Catálogo!$Z:Z,Catálogo!$A:$A,$A13),1000),400000) | X13: =MAX(CEILING(SUMIFS(Catálogo!$AA:AA,Catálogo!$A:$A,$A13),1000),400000) | Y13: =K13 | AA13: =SUMIFS(Catálogo!$F:$F,Catálogo!$A:$A,$A13) | AB13: =SUMIFS(Catálogo!$Z:Z,Catálogo!$A:$A,$A13) | AC13: =SUMIFS(Catálogo!$H:$H,Catálogo!$A:$A,$A13) | AD13: =SUMIFS(Catálogo!$Z:Z,Catálogo!$A:$A,$A13) | AE13: =SUMIFS(Catálogo!$J:$J,Catálogo!$A:$A,$A13) | AF13: =SUMIFS(Catálogo!$Z:Z,Catálogo!$A:$A,$A13) | AG13: =SUMIFS(Catálogo!$L:$L,Catálogo!$A:$A,$A13) | AH13: =SUMIFS(Catálogo!$Z:Z,Catálogo!$A:$A,$A13) | AI13: =SUMIFS(Catálogo!$N:$N,Catálogo!$A:$A,$A13) | AJ13: =SUMIFS(Catálogo!$Z:Z,Catálogo!$A:$A,$A13)
... A29: PIPE-01 | B29: Automatizacion de pipeline/scripts/tools | C29: pipeline | D29: 1-80 | E29: =IF(SUMIFS(Catálogo!$F:$F,Catálogo!$A:$A,$A29)=0,SUMIFS(Catálogo!$H:$H,Catálogo!$A:$A,$A29),SUMIFS(Catálogo!$F:$F,Catálogo!$A:$A,$A29)) | F29: =IF(SUMIFS(Catálogo!$G:$G,Catálogo!$A:$A,$A29)=0,SUMIFS(Catálogo!$I:$I,Catálogo!$A:$A,$A29),SUMIFS(Catálogo!$G:$G,Catálogo!$A:$A,$A29)) | G29: =IF(SUMIFS(Catálogo!$F:$F,Catálogo!$A:$A,$A29)=0,MAX(FLOOR(SUMIFS(Catálogo!$T:$T,Catálogo!$A:$A,$A29),1000),400000),MAX(FLOOR(SUMIFS(Catálogo!$R:$R,Catálogo!$A:$A,$A29),1000),400000)) | H29: =IF(SUMIFS(Catálogo!$G:$G,Catálogo!$A:$A,$A29)=0,MAX(CEILING(SUMIFS(Catálogo!$U:$U,Catálogo!$A:$A,$A29),1000),400000),MAX(CEILING(SUMIFS(Catálogo!$S:$S,Catálogo!$A:$A,$A29),1000),400000)) | I29: =SUMIFS(Catálogo!$H:$H,Catálogo!$A:$A,$A29) | J29: =SUMIFS(Catálogo!$I:$I,Catálogo!$A:$A,$A29) | K29: =MAX(FLOOR(SUMIFS(Catálogo!$T:T,Catálogo!$A:$A,$A29),1000),400000) | L29: =MAX(CEILING(SUMIFS(Catálogo!$U:U,Catálogo!$A:$A,$A29),1000),400000) | M29: =SUMIFS(Catálogo!$J:$J,Catálogo!$A:$A,$A29) | N29: =SUMIFS(Catálogo!$K:$K,Catálogo!$A:$A,$A29) | O29: =MAX(FLOOR(SUMIFS(Catálogo!$V:V,Catálogo!$A:$A,$A29),1000),400000) | P29: =MAX(CEILING(SUMIFS(Catálogo!$W:W,Catálogo!$A:$A,$A29),1000),400000) | Q29: =SUMIFS(Catálogo!$L:$L,Catálogo!$A:$A,$A29) | R29: =SUMIFS(Catálogo!$M:$M,Catálogo!$A:$A,$A29) | S29: =MAX(FLOOR(SUMIFS(Catálogo!$X:X,Catálogo!$A:$A,$A29),1000),400000) | T29: =MAX(CEILING(SUMIFS(Catálogo!$Y:Y,Catálogo!$A:$A,$A29),1000),400000) | U29: =SUMIFS(Catálogo!$N:$N,Catálogo!$A:$A,$A29) | V29: =SUMIFS(Catálogo!$O:$O,Catálogo!$A:$A,$A29) | W29: =MAX(FLOOR(SUMIFS(Catálogo!$Z:Z,Catálogo!$A:$A,$A29),1000),400000) | X29: =MAX(CEILING(SUMIFS(Catálogo!$AA:AA,Catálogo!$A:$A,$A29),1000),400000) | Y29: =K29 | AA29: =SUMIFS(Catálogo!$F:$F,Catálogo!$A:$A,$A29) | AB29: =SUMIFS(Catálogo!$Z:Z,Catálogo!$A:$A,$A29) | AC29: =SUMIFS(Catálogo!$H:$H,Catálogo!$A:$A,$A29) | AD29: =SUMIFS(Catálogo!$Z:Z,Catálogo!$A:$A,$A29) | AE29: =SUMIFS(Catálogo!$J:$J,Catálogo!$A:$A,$A29) | AF29: =SUMIFS(Catálogo!$Z:Z,Catálogo!$A:$A,$A29) | AG29: =SUMIFS(Catálogo!$L:$L,Catálogo!$A:$A,$A29) | AH29: =SUMIFS(Catálogo!$Z:Z,Catálogo!$A:$A,$A29) | AI29: =SUMIFS(Catálogo!$N:$N,Catálogo!$A:$A,$A29) | AJ29: =SUMIFS(Catálogo!$Z:Z,Catálogo!$A:$A,$A29)

Sheet Cotizador Web
A1: Cómo cada decisión del wizard se refleja en tiempos y precios
A3: Regla general: el wizard mapea tus respuestas a VARIABLES de un servicio (serviceVariables.ts); esas variables eligen el NIVEL (tierMap) y el nivel define horas → precio (Resumen Servicios). Si el modelo no existe o es CAD, se SUMA un segundo servicio (RTA-01 creación / CAD-01 conversión).
A7: A. Decisiones → efecto exacto
A8: Rama | B8: Pregunta / decisión | C8: Si dices N… | D8: Se mapea a | E8: Efecto en precio
A9: Todas web-3D | B9: ¿Ya tienes el modelo 3D? → No | C9: — | D9: Se SUMA RTA-01 (creación desde cero) como servicio extra | E9: Suma el rango completo de RTA-01 al total
A10: Todas web-3D | B10: ¿Ya tienes el modelo? → Sí + formato STEP o CAD limpio | C10: — | D10: Se SUMA CAD-01 (conversión) como servicio extra | E10: Suma el rango completo de CAD-01
A11: Todas web-3D | B11: Sí + escaneo o solo fotos | C11: — | D11: Se SUMA RTA-01 como "preparación del modelo" | E11: Suma RTA-01 (nivel según detalle elegido)
A12: Todas web-3D | B12: Sí + glTF/GLB | C12: — | D12: Sin extra (web-ready) | E12: Solo el visor
A13: ver-modelo / interactivo / scrollytelling / web-app | B13: Nivel de detalle = N (1–5 continuo) | C13: N → poligonos interpolados | D13: RTA-01.polyCount = interpolación [4k, 9k, 40k, 120k, 300k] redondeada a 500 | E13: Cambia el tier de RTA-01 (≤10k S · ≤50k M · ≤150k L)
A14: ver-modelo / interactivo / scrollytelling / web-app | B14: Superficie = N (1–5) | C14: N → tipoSuperficie | D14: RTA-01.tipoSuperficie | E14: ≤2 S · 3 M · 4 L · 5 XL (+nota discovery)
A15: ver-modelo / interactivo / scrollytelling / web-app | B15: Cantidad de piezas = N | C15: N → numPiezas | D15: RTA-01.numPiezas / CAD-01.numPiezas | E15: ≤8 S · ≤30 M · ≤100 L (CAD: ≤15 S · ≤60 M · ≤300 L)
A16: ver-modelo / interactivo / scrollytelling / web-app | B16: Acabados = simple / variado / detallado | C16: — | D16: RTA-01.numTexturas = 1 / 3 / 6 | E16: Sube el tier si cruza umbrales de otras variables
A17: ver-modelo | B17: Interfaz del visor = hotspots (avanzado) | C17: — | D17: WEB-01.numHotspots = 8 | E17: ≤5 S · ≤15 M · ≤30 L
A18: ver-modelo | B18: Dónde se muestra = feria / móvil / landing | C18: — | D18: WEB-01.target = Desktop + móvil | E18: tier M (vs Desktop = S)
A19: interactivo | B19: Tipo de interactividad = configurar O plataforma = app | C19: — | D19: Cambia el servicio a WEB-04 (Web App) | E19: WEB-04 es más costoso que WEB-01
... A25: web-app | B25: Origen de datos = CMS / API (avanzado) | C25: — | D25: WEB-04.fuenteDatos | E25: CMS tier M · API tier L
A27: B. Umbrales EXACTOS (tierMaps) que usa derivarTier
A28: Servicio | B28: Variable | C28: Umbral → nivel
A29: RND-01 | B29: numImagenes | C29: ≤2 → S · ≤5 → M · ≤12 → L
A30: RND-01 | B30: numMateriales | C30: ≤3 → S · ≤6 → M · ≤99 → L
A31: RND-01 | B31: resolucion | C31: Web (≤2K) → S · Print (4K+) → M
A32: RND-02 | B32: duracion | C32: ≤10 → S · ≤30 → M · ≤90 → L
A33: RND-02 | B33: numShots | C33: ≤2 → S · ≤4 → M · ≤12 → L
A34: RTA-01 | B34: polyCount | C34: ≤10000 → S · ≤50000 → M · ≤150000 → L
A35: RTA-01 | B35: numPiezas | C35: ≤8 → S · ≤30 → M · ≤100 → L
A36: RTA-01 | B36: tipoSuperficie | C36: ≤2 → S · ≤3 → M · ≤4 → L · ≤5 → XL
A37: RTA-01 | B37: fuente | C37: Ya tengo el modelo 3D → S · Desde CAD (requiere conversión) → M · Desde fotos (requiere modelado) → L
A38: RTA-01 | B38: numTexturas | C38: ≤2 → S · ≤4 → M · ≤10 → L
A39: RTA-02 | B39: polyCount | C39: ≤10000 → S · ≤50000 → M · ≤150000 → L
... A78: CAD-01 | B78: target | C78: Desktop web → S · Móvil exigente → M
A80: C. Ejemplo resuelto con FÓRMULAS VIVAS (ver-modelo, "No tengo modelo", nivel 3, 12 piezas, detallado, superficie 3)
A81: Paso | B81: Cálculo | C81: Resultado (celda viva)
A82: 1. RTA-01.polyCount | B82: nivel 3 → interpolación [4k, 9k, 40k, 120k, 300k] = 40.000 | C82: polyCount = 40.000
A83: 2. RTA-01.numPiezas | B83: slider piezas = 12 | C83: ='Resumen Servicios'!I7
A84: 3. RTA-01.numTexturas | B84: acabado detallado → 6 sets | C84: ='Resumen Servicios'!O4
A85: 4. RTA-01.tipoSuperficie | B85: superficie 3 | C85: ='Resumen Servicios'!K7
A86: 5. Tier RTA-01 | B86: máximo de los umbrales (piezas ≤30 → M) | C86: ='Resumen Servicios'!P4
A87: 6. WEB-01 | B87: sin hotspots, sin CMS → Desktop, 0 hotspots | C87: =MAX(FLOOR(('Resumen Servicios'!K7+'Resumen Servicios'!O4)*0.95,1000),400000)
A88: 7. WEB-01 S → ver Resumen fila WEB-01 | B88: motor computeQuote | C88: =CEILING(('Resumen Servicios'!L7+'Resumen Servicios'!P4)*0.95,1000)
A89: 8. RTA-01 M → ver Resumen fila RTA-01 | B89: motor computeQuote
...

Sheet Benchmark CO vs Intl
A1: Precios por hora — Colombia vs Internacional (2025-2026)
A3: Perfil | B3: Colombia COP/h | C3: Internacional USD/h | D3: Nota
A4: Dev web general junior (CO) | B4: 60.000–100.000 | C4: $15–25 | D4: omarhernandezrey.com/blog
A5: Dev web general mid (CO) | B5: 100.000–160.000 | C5: $25–40 | D5: omarhernandezrey.com/blog
A6: Dev web senior / clientes intl. (CO) | B6: 160.000–240.000+ | C6: $40–60+ | D6: omarhernandezrey.com/blog
A7: Three.js/WebGL LatAm (placement) | B7: ≈ 80.000–85.000 | C7: ≈ $20 | D7: hireinsouth.com ($3.500/mes)
A8: Modelador 3D experimentado (CO) | B8: 40.000–60.000 | C8: ≈ $10–15 | D8: comunidad CO
A9: Diseño profesional (tarifario CO 2025) | B9: ≈ 90.000 | C9: — | D9: disenadorescolombianos.co
A10: 3D artistas mercados internacionales | B10: ≈ 2,8M–4M /día | C10: $700–1.000/día | D10: benchmark global
A11: Tu RC-WEB actual | B11: 40.000–57.000 | C11: $10–14 | D11: ← por debajo del junior: margen de reventa sano
A12: Tu RC-ART actual | B12: 30.000–42.000 | C12: $7,5–10,5 | D12: ← en línea con modelador local
A13: Tu RC-CON actual | B13: 60.000–82.000 | C13: $15–20,5 | D13: ← muy por debajo del senior internacional
A15: IA (referencia por proyecto, Colombia): chatbot conversacional $6M–16M COP · packs agencia $1,89M–$4,89M · agente empresarial $20.000–80.000 USD (techo internacional).
A17: Fuentes: omarhernandezrey.com · hireinsouth.com · disenadorescolombianos.co · consolidaciondigital.com · mentoracolombia.com · kemenystudio.com

Sheet Mapeo
A1: Umbrales EXACTOS que usa la web (serviceVariables.ts) — NO editar salvo cambio de alcance
A3: Variable | B3: tope S | C3: tope M | D3: tope L | E3: tope XL
A4: RTA-01.polyCount (tris) | B4: 10000 | C4: 50000 | D4: 150000 | E4: 999999999 | F4: XS · S · M · L · XL
A5: RTA-01.numPiezas | B5: 8 | C5: 30 | D5: 100 | E5: 999999999 | F5: XS · S · M · L · XL
A6: RTA-01.tipoSuperficie | B6: 2 | C6: 3 | D6: 4 | E6: 999999999 | F6: XS · S · M · L · XL
A7: CAD-01.numPiezas | B7: 15 | C7: 60 | D7: 150 | E7: 999999999 | F7: XS · S · M · L · XL
A8: WEB-01.numHotspots | B8: 5 | C8: 15 | D8: 30 | E8: 999999999 | F8: XS · S · M · L · XL
A9: WEB-04.numVariantes | B9: 10 | C9: 25 | D9: 50 | E9: 999999999 | F9: XS · S · M · L · XL
A10: WEB-04.numSKUs | B10: 5 | C10: 20 | D10: 100 | E10: 999999999 | F10: XS · S · M · L · XL
A11: WEB-05.numSecciones | B11: 4 | C11: 8 | D11: 15 | E11: 999999999 | F11: XS · S · M · L · XL
A12: WEB-07.numProductos | B12: 5 | C12: 20 | D12: 100 | E12: 999999999 | F12: XS · S · M · L · XL
A14: Opciones → nivel (selects)
A15: Variable | B15: Opción | C15: Nivel (2=S, 3=M, 4=L)
A16: RTA-01.fuente | B16: Ya tengo el modelo 3D | C16: 2
A17: RTA-01.fuente | B17: Desde CAD (requiere conversión) | C17: 3
A18: RTA-01.fuente | B18: Desde fotos (requiere modelado) | C18: 4
A19: WEB-01.target | B19: Desktop | C19: 2
A20: WEB-01.target | B20: Desktop + móvil | C20: 3
A21: WEB-01.datos | B21: Fijos (hardcode) | C21: 2
A22: WEB-01.datos | B22: Dinámicos (CMS/API) | C22: 3
A23: WEB-04.fuenteDatos | B23: Estáticos (JSON local) | C23: 2
A24: WEB-04.fuenteDatos | B24: CMS | C24: 3
A25: WEB-04.fuenteDatos | B25: API externa | C25: 4
A26: WEB-04.auth | B26: NO | C26: 2
A27: WEB-04.auth | B27: SI | C27: 4
... A32: WEB-06.scores | B32: SI | C32: 3

Sheet Simulador Web
A1: SIMULADOR WEB — replica exactamente la lógica del cotizador
A2: Edita solo las celdas AMARILLAS. Todo lo demás se recalcula conectado a Tarifas y Catálogo.
A4: ENTRADAS — el wizard
A5: Rama (¿qué quieres lograr?) | B5: ver-modelo | C5: web-app → WEB-04/06/07 · scrollytelling → WEB-05 · interactivo → WEB-01/04 · ver-modelo → WEB-01
A6: Tipo de interactividad (solo interactivo) | B6: rotar | C6: configurar → WEB-04 · hotspots → visor con hotspots
A7: Tipo de app (solo web-app) | B7: configurador | C7: catalogo → WEB-07 · juego → WEB-06 · resto → WEB-04
A8: Plataforma (solo interactivo) | B8: mi-web | C8: app → WEB-04 · feria/móvil → exige móvil
A9: ¿Modelo 3D? | B9: si-gltf | C9: no-crear → CREACIÓN (RTA-01) · si-step → CONVERSIÓN (CAD-01) · si-scan → PREPARACIÓN (RTA-01) · si-gltf/si-otro → sin extra
A10: Nivel de detalle (1–5 continuo) | B10: 3 | C10: RTA-01.polyCount interpolado: 1→4k · 2→9k · 3→40k · 4→120k · 5→300k (tris)
A11: Superficie (1–5 continuo) | B11: 3 | C11: RTA-01.tipoSuperficie: ≤2 S · 3 M · 4 L · 5 XL (+discovery)
A12: Cantidad de piezas (1–50) | B12: 12 | C12: RTA-01/CAD-01.numPiezas: ≤8 S · ≤30 M · ≤100 L
A13: Acabados | B13: detallado | C13: RTA-01.numTexturas: simple 1 · variado 3 · detallado 6
A14: Interfaz del visor (avanzado) | B14: limpio | C14: hotspots → WEB-01.numHotspots = 8 (sube a M)
A15: Dónde se muestra | B15: mi-web | C15: feria/móvil/landing → Desktop + móvil (sube a M)
A16: Escenas (solo scrollytelling, 1–15) | B16: 8 | C16: WEB-05.numSecciones: ≤4 S · ≤8 M · ≤15 L
A17: Usuarios de la app (avanzado) | B17: publico | C17: equipo-interno → WEB-04.auth = SI (sube a L)
A18: Origen de datos (avanzado) | B18: estaticos | C18: cms → tier M · api → tier L (WEB-04)
A21: SUPUESTOS ASUMIDOS (no se preguntan — ajústalos si lo necesitas)
A22: WEB-04 · numSKUs (¿para cuántos productos?) | B22: 1 | C22: ≤5 S · ≤20 M · ≤100 L
A23: WEB-06 · scores (leaderboard) | B23: NO | C23: sube a M
A24: WEB-06 · mecánica | B24: Media (runner, plataforma) | C24: Simple S · Media M · Compleja L
A27: DERIVADOS — calculados por la lógica de la web
A28: Servicio principal | B28: =IF($B$4="web-app",IF($B$7="catalogo","WEB-07",IF($B$7="juego","WEB-06","WEB-04")),IF($B$4="scrollytelling","WEB-05",IF($B$4="interactivo",IF(OR($B$6="configurar",$B$8="app"),"WEB-04","WEB-01"),"WEB-01"))) | C28: Así enruta el wizard según rama y respuestas
A29: ¿Suma CREACIÓN del modelo? (RTA-01) | B29: =IF($B$9="no-crear","SI","NO")
A30: ¿Suma CONVERSIÓN CAD? (CAD-01) | B30: =IF($B$9="si-step","SI","NO") | C30: CAD limpio → conversión; escaneo/fotos → preparación (también RTA-01)
A31: ¿Suma PREPARACIÓN de modelo? (RTA-01) | B31: =IF($B$9="si-scan","SI","NO")
A32: RTA-01 · polyCount | B32: =ROUND((LOOKUP($B$10,{1,2,3,4,5},{4000,9000,40000,120000,300000})+(LOOKUP($B$10+0.5,{1,2,3,4,5},{4000,9000,40000,120000,300000})-LOOKUP($B$10,{1,2,3,4,5},{4000,9000,40000,120000,300000}))*MOD($B$10,1))/500)*500 | C32: Interpolación continua entre etapas, redondeada a 500
A33: RTA-01 · numPiezas | B33: =$B$12
A34: RTA-01 · numTexturas | B34: =IF($B$13="simple",1,IF($B$13="variado",3,6))
A35: RTA-01 · tipoSuperficie | B35: =ROUND($B$11,1)
A36: CAD-01 · numPiezas | B36: =$B$12
A37: WEB-01 · numHotspots | B37: =IF($B$14="hotspots",8,0)
A38: WEB-01 · target | B38: =IF(OR($B$8="feria",$B$8="movil",$B$8="landing"),"Desktop + móvil","Desktop")
A39: WEB-05 · numSecciones | B39: =$B$16
A40: WEB-04 · numVariantes | B40: =$B$15
A41: WEB-04 · auth | B41: =IF($B$17="equipo-interno","SI","NO")
A42: WEB-04 · fuenteDatos | B42: =IF($B$18="cms","CMS",IF($B$18="api","API externa","Estáticos (JSON local)"))
A43: WEB-07 · numProductos | B43: 10 | C43: Asumido: 10 (editable)
A47: NIVEL (tier) derivado por servicio — máx entre umbrales (igual que derivarTier)
A49: Nivel WEB-01 | B49: =MAX(IFERROR(MATCH($B$37,Mapeo!$B$8:$E$8,1),0)+1,2) | C49: =INDEX({"XS","S","M","L","XL"},B49) | D49: ← nivel idx / nombre
...
